<?xml version="1.0"?>
<robot name="blocky" xmlns:xacro="http://ros.org/wiki/xacro">


  <!-- Set up some variables and defaults -->
  <xacro:property name="width" value="0.2" />
  
  <material name="blue">
    <color rgba="0 0 0.8 1"/>
  </material>

  <material name="green">
    <color rgba="0 0.8 0 1"/>
  </material>

  <xacro:macro name="default_inertial" params="mass">
    <inertial>
      <mass value="${mass}" />
      <inertia ixx="1.0" ixy="0.0" ixz="0.0" iyy="1.0" iyz="0.0" izz="1.0" />
    </inertial>
  </xacro:macro>

  
  <!-- Define Links-->
  <link name="base_link">
    <visual>
      <geometry>
        <box size="${width} ${width} ${width}"/>
      </geometry>
      <material name="blue"/>
    </visual>
    <collision>
      <geometry>
        <box size="${width} ${width} ${width}"/>
      </geometry>
    </collision>
    <xacro:default_inertial mass="10"/>
  </link>

  <link name="head">
    <visual>
      <geometry>
        <box size="${width} ${width} ${width}"/>
      </geometry>
      <material name="green"/>
    </visual>
    <collision>
      <geometry>
        <box size="${width} ${width} ${width}"/>
      </geometry>
    </collision>
    <xacro:default_inertial mass="2"/>
  </link>


  <!-- Define Joints -->
  <joint name="joint1" type="continuous">
    <parent link="base_link"/>
    <child link="head"/>
    <axis xyz="0 0 1"/>
    <origin xyz="0 0 ${width}"/>
    <limit effort="30" velocity="1.0"/>
  </joint>


  <!-- Define Transmissions -->
  <transmission name="joint1_trans">
    <type>transmission_interface/SimpleTransmission</type>
    <actuator name="$joint1_motor">
      <mechanicalReduction>1</mechanicalReduction>
    </actuator>
    <joint name="joint1">
      <hardwareInterface>PositionJointInterface</hardwareInterface>
    </joint>
  </transmission>


  <!-- Gazebo plugin for ROS Control -->
  <gazebo>
    <plugin name="gazebo_ros_control" filename="libgazebo_ros_control.so">
      <robotNamespace>/</robotNamespace>
    </plugin>
  </gazebo>

</robot>
